<?xml version="1.0" ?>
<!-- =================================================================================== -->
<!-- |    This document was autogenerated by xacro from niryo_one_gripper1_n_camera.urdf.xacro | -->
<!-- |    EDITING THIS FILE BY HAND IS NOT RECOMMENDED                                 | -->
<!-- =================================================================================== -->
<robot name="niryo_one">
  <!-- Enable Gazebo control-->
  <gazebo>
    <plugin filename="libgazebo_ros_control.so" name="gazebo_ros_control">
      <robotSimType>gazebo_ros_control/DefaultRobotHWSim</robotSimType>
    </plugin>
  </gazebo>
  <!-- Properties -->
  <!-- Properties -->
  <!-- Links -->
  <link name="world"/>
  <link name="base_link">
    <visual>
      <origin rpy="0 0 0" xyz="0 0 0"/>
      <geometry>
        <mesh filename="package://niryo_robot_description/meshes/one/collada/base_link.dae"/>
      </geometry>
    </visual>
    <collision>
      <origin rpy="0 0 0" xyz="0 0 0"/>
      <geometry>
        <mesh filename="package://niryo_robot_description/meshes/one/stl/base_link.stl"/>
      </geometry>
    </collision>
    <inertial>
      <origin rpy="0 0 0" xyz="0 0 0.0515"/>
      <mass value="1.2"/>
      <inertia ixx="0.0015" ixy="0.0" ixz="0.0" iyy="0.0015" iyz="0.0" izz="0.0015"/>
    </inertial>
  </link>
  <link name="shoulder_link">
    <visual>
      <origin rpy="0 0 0" xyz="0 0 0"/>
      <geometry>
        <mesh filename="package://niryo_robot_description/meshes/one/collada/shoulder_link.dae"/>
      </geometry>
    </visual>
    <collision>
      <origin rpy="0 0 0" xyz="0 0 0"/>
      <geometry>
        <mesh filename="package://niryo_robot_description/meshes/one/stl/shoulder_link.stl"/>
      </geometry>
    </collision>
    <inertial>
      <origin rpy="0 0 0" xyz="0 0 0.04"/>
      <mass value="0.8"/>
      <inertia ixx="0.0015" ixy="0.0" ixz="0.0" iyy="0.0015" iyz="0.0" izz="0.0015"/>
    </inertial>
  </link>
  <link name="arm_link">
    <visual>
      <origin rpy="0 0 0" xyz="0 0 0"/>
      <geometry>
        <mesh filename="package://niryo_robot_description/meshes/one/collada/arm_link.dae"/>
      </geometry>
    </visual>
    <collision>
      <origin rpy="0 0 0" xyz="0 0 0"/>
      <geometry>
        <mesh filename="package://niryo_robot_description/meshes/one/stl/arm_link.stl"/>
      </geometry>
    </collision>
    <inertial>
      <origin rpy="0 0 0" xyz="0.105 -0.1 0"/>
      <mass value="0.4"/>
      <inertia ixx="0.0015" ixy="0.0" ixz="0.0" iyy="0.0015" iyz="0.0" izz="0.0015"/>
    </inertial>
  </link>
  <link name="elbow_link">
    <visual>
      <origin rpy="0 0 0" xyz="0 0 0"/>
      <geometry>
        <mesh filename="package://niryo_robot_description/meshes/one/collada/elbow_link.dae"/>
      </geometry>
    </visual>
    <collision>
      <origin rpy="0 0 0" xyz="0 0 0"/>
      <geometry>
        <mesh filename="package://niryo_robot_description/meshes/one/stl/elbow_link.stl"/>
      </geometry>
    </collision>
    <inertial>
      <origin rpy="0 0 0" xyz="0.02075 0.015 0"/>
      <mass value="0.3"/>
      <inertia ixx="0.0015" ixy="0.0" ixz="0.0" iyy="0.0015" iyz="0.0" izz="0.0015"/>
    </inertial>
  </link>
  <link name="forearm_link">
    <visual>
      <origin rpy="0 0 0" xyz="0 0 0"/>
      <geometry>
        <mesh filename="package://niryo_robot_description/meshes/one/collada/forearm_link.dae"/>
      </geometry>
    </visual>
    <collision>
      <origin rpy="0 0 0" xyz="0 0 0"/>
      <geometry>
        <mesh filename="package://niryo_robot_description/meshes/one/stl/forearm_link.stl"/>
      </geometry>
    </collision>
    <inertial>
      <origin rpy="0 0 0" xyz="0 0 0.09"/>
      <mass value="0.3"/>
      <inertia ixx="0.0015" ixy="0.0" ixz="0.0" iyy="0.0015" iyz="0.0" izz="0.0015"/>
    </inertial>
  </link>
  <link name="wrist_link">
    <visual>
      <origin rpy="0 0 0" xyz="0 0 0"/>
      <geometry>
        <mesh filename="package://niryo_robot_description/meshes/one/collada/wrist_link.dae"/>
      </geometry>
    </visual>
    <collision>
      <origin rpy="0 0 0" xyz="0 0 0"/>
      <geometry>
        <mesh filename="package://niryo_robot_description/meshes/one/stl/wrist_link.stl"/>
      </geometry>
    </collision>
    <inertial>
      <origin rpy="0 0 0" xyz="0.0082 -0.00275 0"/>
      <mass value="0.15"/>
      <inertia ixx="0.001" ixy="0.0" ixz="0.0" iyy="0.001" iyz="0.0" izz="0.001"/>
    </inertial>
  </link>
  <link name="hand_link">
    <visual>
      <origin rpy="0 0 0" xyz="0 0 0"/>
      <geometry>
        <mesh filename="package://niryo_robot_description/meshes/one/collada/hand_link.dae"/>
      </geometry>
    </visual>
    <collision>
      <origin rpy="0 0 0" xyz="0 0 0"/>
      <geometry>
        <mesh filename="package://niryo_robot_description/meshes/one/stl/hand_link.stl"/>
      </geometry>
    </collision>
    <inertial>
      <origin rpy="0 0 0" xyz="0 0 0.00365"/>
      <mass value="0.05"/>
      <inertia ixx="0.001" ixy="0.0" ixz="0.0" iyy="0.001" iyz="0.0" izz="0.001"/>
    </inertial>
  </link>
  <link name="tool_link">
    </link>
  <!-- add collision for the motor of joint 5 -->
  <link name="joint5_motor">
    <collision>
      <origin rpy="0 0 0" xyz="-0.045 0.0 0.1765"/>
      <geometry>
        <box size="0.0435 0.0285 0.0465"/>
      </geometry>
    </collision>
  </link>
  <!--Joints -->
  <joint name="joint_world" type="fixed">
    <parent link="world"/>
    <child link="base_link"/>
    <origin rpy="0 0 0" xyz="0 0 0"/>
  </joint>
  <joint name="joint_1" type="revolute">
    <parent link="base_link"/>
    <child link="shoulder_link"/>
    <origin rpy="0 0 0" xyz="0 0 0.103"/>
    <axis xyz="0 0 1"/>
    <limit effort="10.0" lower="-3.0543261909902775" upper="3.0543261909902775" velocity="2.2"/>
    <dynamics damping="0.1" friction="0.0"/>
  </joint>
  <joint name="joint_2" type="revolute">
    <parent link="shoulder_link"/>
    <child link="arm_link"/>
    <origin rpy="1.570796326795 -1.570796326795 0" xyz="0 0 0.08"/>
    <limit effort="10.0" lower="-1.9100883333827199" upper="0.6400122367063628" velocity="2.2"/>
    <axis xyz="0 0 1"/>
    <dynamics damping="0.1" friction="0.0"/>
  </joint>
  <joint name="joint_3" type="revolute">
    <parent link="arm_link"/>
    <child link="elbow_link"/>
    <origin rpy="0 0 -1.570796326795" xyz="0.21 0.0 0"/>
    <limit effort="7.0" lower="-1.3943435394183616" upper="1.5700981950942021" velocity="2.0"/>
    <axis xyz="0 0 1"/>
    <dynamics damping="0.1" friction="0.0"/>
  </joint>
  <joint name="joint_4" type="revolute">
    <parent link="elbow_link"/>
    <child link="forearm_link"/>
    <origin rpy="0 1.570796326795 0" xyz="0.0415 0.03 0"/>
    <limit effort="7.0" lower="-3.050137400785491" upper="3.0543261909902775" velocity="2.0"/>
    <axis xyz="0 0 1"/>
    <dynamics damping="0.1" friction="0.0"/>
  </joint>
  <joint name="joint_5" type="revolute">
    <parent link="forearm_link"/>
    <child link="wrist_link"/>
    <origin rpy="0 -1.570796326795 0" xyz="0 0 0.18"/>
    <limit effort="6.0" lower="-1.7453292519944443" upper="1.9200367101190883" velocity="2.0"/>
    <axis xyz="0 0 1"/>
    <dynamics damping="0.1" friction="0.0"/>
  </joint>
  <joint name="joint_6" type="revolute">
    <parent link="wrist_link"/>
    <child link="hand_link"/>
    <origin rpy="0 1.570796326795 0" xyz="0.0164 -0.0055 0"/>
    <limit effort="5.0" lower="-2.530029283691147" upper="2.530029283691147" velocity="2.0"/>
    <axis xyz="0 0 1"/>
    <dynamics damping="0.1" friction="0.0"/>
  </joint>
  <joint name="hand_tool_joint" type="fixed">
    <parent link="hand_link"/>
    <child link="tool_link"/>
    <origin rpy="-1.570796326795 -1.570796326795 0" xyz="0 0 0.0073"/>
  </joint>
  <!-- add collision for the motor of joint 5 -->
  <joint name="joint_test" type="fixed">
    <origin rpy="0 0 0" xyz="0 0 0"/>
    <parent link="forearm_link"/>
    <child link="joint5_motor"/>
  </joint>
  <transmission name="transmission_1">
    <type>transmission_interface/SimpleTransmission</type>
    <joint name="joint_1">
      <hardwareInterface>hardware_interface/PositionJointInterface</hardwareInterface>
    </joint>
    <actuator name="motor_1">
      <mechanicalReduction>1</mechanicalReduction>
    </actuator>
  </transmission>
  <transmission name="transmission_2">
    <type>transmission_interface/SimpleTransmission</type>
    <joint name="joint_2">
      <hardwareInterface>hardware_interface/PositionJointInterface</hardwareInterface>
    </joint>
    <actuator name="motor_2">
      <mechanicalReduction>1</mechanicalReduction>
    </actuator>
  </transmission>
  <transmission name="transmission_3">
    <type>transmission_interface/SimpleTransmission</type>
    <joint name="joint_3">
      <hardwareInterface>hardware_interface/PositionJointInterface</hardwareInterface>
    </joint>
    <actuator name="motor_3">
      <mechanicalReduction>1</mechanicalReduction>
    </actuator>
  </transmission>
  <transmission name="transmission_4">
    <type>transmission_interface/SimpleTransmission</type>
    <joint name="joint_4">
      <hardwareInterface>hardware_interface/PositionJointInterface</hardwareInterface>
    </joint>
    <actuator name="motor_4">
      <mechanicalReduction>1</mechanicalReduction>
    </actuator>
  </transmission>
  <transmission name="transmission_5">
    <type>transmission_interface/SimpleTransmission</type>
    <joint name="joint_5">
      <hardwareInterface>hardware_interface/PositionJointInterface</hardwareInterface>
    </joint>
    <actuator name="motor_5">
      <mechanicalReduction>1</mechanicalReduction>
    </actuator>
  </transmission>
  <transmission name="transmission_6">
    <type>transmission_interface/SimpleTransmission</type>
    <joint name="joint_6">
      <hardwareInterface>hardware_interface/PositionJointInterface</hardwareInterface>
    </joint>
    <actuator name="motor_6">
      <mechanicalReduction>1</mechanicalReduction>
    </actuator>
  </transmission>
  <!-- Joint for camera -->
  <joint name="camera_joint" type="fixed">
    <axis xyz="0 0 1"/>
    <origin rpy="-1.570796326795 0 0" xyz="0 0.025 0"/>
    <parent link="wrist_link"/>
    <child link="camera_link"/>
  </joint>
  <!-- Camera link -->
  <link name="camera_link">
    <collision>
      <origin rpy="0 0 0" xyz="0 0 0"/>
      <geometry>
        <box size="0.03 0.03 0.02"/>
      </geometry>
    </collision>
    <visual>
      <origin rpy="0 0 0" xyz="0 0 0"/>
      <geometry>
        <box size="0.03 0.03 0.02"/>
      </geometry>
      <material name="DarkGrey"/>
    </visual>
    <inertial>
      <mass value="0.05"/>
      <origin rpy="0 0 0" xyz="0 0 0"/>
      <inertia ixx="5.4e-6" ixy="0" ixz="0" iyy="5.4e-6" iyz="0" izz="7.5e-6"/>
    </inertial>
  </link>
  <!-- Add gazebo settings to make the link an camera ! -->
  <gazebo reference="camera_link">
    <material>Gazebo/DarkGrey</material>
    <sensor name="camera_gazebo" type="camera">
      <update_rate>15.0</update_rate>
      <camera name="head">
        <!--69,33 degrees-->
        <horizontal_fov>1.21</horizontal_fov>
        <!--  <aspect_ratio>1.333</aspect_ratio>-->
        <image>
          <width>640</width>
          <height>480</height>
          <format>R8G8B8</format>
        </image>
        <clip>
          <near>0.03</near>
          <far>2</far>
        </clip>
        <distortion>
          <k1>-0.4146402</k1>
          <k2>0.2407384</k2>
          <p1>-0.0</p1>
          <p2>-0.0</p2>
          <k3>-0.1040042</k3>
          <center>0.5 0.5</center>
        </distortion>
      </camera>
      <plugin filename="libgazebo_ros_camera.so" name="camera_controller">
        <alwaysOn>true</alwaysOn>
        <updateRate>0.0</updateRate>
        <cameraName>gazebo_camera</cameraName>
        <imageTopicName>image_raw</imageTopicName>
        <cameraInfoTopicName>camera_info</cameraInfoTopicName>
        <frameName>camera_link</frameName>
      </plugin>
    </sensor>
  </gazebo>
  <!-- gazebo joint state publisher for all joints. Necessary to control mors -->
  <gazebo>
    <plugin filename="libgazebo_ros_joint_state_publisher.so" name="passive_joint_state_publisher">
      <jointName>joint_1, joint_2, joint_3, joint_4, joint_5, joint_6,
                joint_base_to_mors_1, joint_base_to_mors_2
            </jointName>
      <updateRate>50.0</updateRate>
      <alwaysOn>true</alwaysOn>
    </plugin>
  </gazebo>
  <!-- Joint from tool_link to base_gripper -->
  <joint name="joint_to_gripper" type="fixed">
    <parent link="tool_link"/>
    <child link="base_gripper_1"/>
    <origin rpy="0 1.570796326795 1.570796326795" xyz="0 0 0"/>
  </joint>
  <!-- Base Gripper -->
  <link name="base_gripper_1">
    <inertial>
      <origin rpy="0 0 0" xyz="0.0028582 0.0022204 0.023772"/>
      <mass value="0.001"/>
      <inertia ixx="1E-06" ixy="0.0" ixz="0.0" iyy="1E-06" iyz="0.0" izz="1E-06"/>
    </inertial>
    <visual>
      <origin rpy="0 0 0" xyz="0 0 0"/>
      <geometry>
        <mesh filename="package://niryo_robot_description/meshes/gripper_1/base_gripper_1.STL"/>
      </geometry>
    </visual>
    <collision>
      <origin rpy="0 0 0" xyz="0 0 0"/>
      <geometry>
        <mesh filename="package://niryo_robot_description/meshes/gripper_1/base_gripper_1.STL"/>
      </geometry>
    </collision>
  </link>
  <!-- Mors 1 -->
  <link name="mors_1">
    <inertial>
      <origin rpy="0 0 0" xyz="-0.0049739 0.0067393 -0.023929"/>
      <mass value="0.0067248"/>
      <inertia ixx="1.1778E-06" ixy="-2.1129E-08" ixz="1.0185E-07" iyy="1.3054E-06" iyz="1.7669E-07" izz="4.3534E-07"/>
    </inertial>
    <visual>
      <origin rpy="0 0 0" xyz="0 0 0"/>
      <geometry>
        <mesh filename="package://niryo_robot_description/meshes/gripper_1/mors_1.STL"/>
      </geometry>
      <material name="">
        <color rgba="0.49804 0.49804 0.49804 1"/>
      </material>
    </visual>
    <collision>
      <origin rpy="0 0 0" xyz="0 0 0"/>
      <geometry>
        <mesh filename="package://niryo_robot_description/meshes/gripper_1/mors_1.STL"/>
      </geometry>
    </collision>
  </link>
  <joint name="joint_base_to_mors_1" type="fixed">
    <origin rpy="1.5708 0 0" xyz="0.01455 -0.0796 0.0096137"/>
    <parent link="base_gripper_1"/>
    <child link="mors_1"/>
    <axis xyz="0 1 0"/>
    <limit effort="1" lower="-0.01" upper="0.01" velocity="5"/>
  </joint>
  <!-- Mors 2 -->
  <link name="mors_2">
    <inertial>
      <origin rpy="0 0 0" xyz="-0.0049739 -0.0067393 -0.023929"/>
      <mass value="0.0067248"/>
      <inertia ixx="1.1778E-06" ixy="2.1129E-08" ixz="1.0185E-07" iyy="1.3054E-06" iyz="-1.7669E-07" izz="4.3534E-07"/>
    </inertial>
    <visual>
      <origin rpy="0 0 0" xyz="0 0 0"/>
      <geometry>
        <mesh filename="package://niryo_robot_description/meshes/gripper_1/mors_2.STL"/>
      </geometry>
    </visual>
    <collision>
      <origin rpy="0 0 0" xyz="0 0 0"/>
      <geometry>
        <mesh filename="package://niryo_robot_description/meshes/gripper_1/mors_2.STL"/>
      </geometry>
    </collision>
  </link>
  <joint name="joint_base_to_mors_2" type="fixed">
    <origin rpy="1.5708 0 0" xyz="0.01455 -0.0796 -0.011066"/>
    <parent link="base_gripper_1"/>
    <child link="mors_2"/>
    <axis xyz="0 -1 0"/>
    <limit effort="1" lower="-0.01" upper="0.01" velocity="5"/>
  </joint>
  <transmission name="transmission_7">
    <type>transmission_interface/SimpleTransmission</type>
    <joint name="joint_base_to_mors_1">
      <hardwareInterface>hardware_interface/EffortJointInterface</hardwareInterface>
    </joint>
    <actuator name="motor_7">
      <mechanicalReduction>1</mechanicalReduction>
    </actuator>
  </transmission>
  <transmission name="transmission_8">
    <type>transmission_interface/SimpleTransmission</type>
    <joint name="joint_base_to_mors_2">
      <hardwareInterface>hardware_interface/EffortJointInterface</hardwareInterface>
    </joint>
    <actuator name="motor_8">
      <mechanicalReduction>1</mechanicalReduction>
    </actuator>
  </transmission>
  <!-- material -->
  <gazebo reference="base_gripper_1">
    <material>Gazebo/DarkGrey</material>
  </gazebo>
  <gazebo reference="mors_1">
    <material>Gazebo/DarkGrey</material>
  </gazebo>
  <gazebo reference="mors_2">
    <material>Gazebo/DarkGrey</material>
  </gazebo>
</robot>

