<?xml version="1.0" ?>
<!-- =================================================================================== -->
<!-- |    This document was autogenerated by xacro from /home/hyeonbeen/catkin_ws_fp/src/mobile_manipulator/mobile_manipulator_description/urdf/mobile_manipulator.xacro | -->
<!-- |    EDITING THIS FILE BY HAND IS NOT RECOMMENDED                                 | -->
<!-- =================================================================================== -->
<robot name="scout_v2">
    <!-- Enable Gazebo control-->
    <!-- Properties -->
    <!-- Properties -->
    <!-- Links -->
    <link name="arm_base_link">
        <visual>
            <origin rpy="0 0 0" xyz="0 0 0" />
            <geometry>
                <mesh filename="package://niryo_robot_description/meshes/one/collada/base_link.dae" />
            </geometry>
        </visual>
        <collision>
            <origin rpy="0 0 0" xyz="0 0 0" />
            <geometry>
                <mesh filename="package://niryo_robot_description/meshes/one/stl/base_link.stl" />
            </geometry>
        </collision>
        <inertial>
            <origin rpy="0 0 0" xyz="0 0 0.0515" />
            <mass value="1.2" />
            <inertia ixx="0.0015" ixy="0.0" ixz="0.0" iyy="0.0015" iyz="0.0" izz="0.0015" />
        </inertial>
    </link>
    <link name="shoulder_link">
        <visual>
            <origin rpy="0 0 0" xyz="0 0 0" />
            <geometry>
                <mesh filename="package://niryo_robot_description/meshes/one/collada/shoulder_link.dae" />
            </geometry>
        </visual>
        <collision>
            <origin rpy="0 0 0" xyz="0 0 0" />
            <geometry>
                <mesh filename="package://niryo_robot_description/meshes/one/stl/shoulder_link.stl" />
            </geometry>
        </collision>
        <inertial>
            <origin rpy="0 0 0" xyz="0 0 0.04" />
            <mass value="0.8" />
            <inertia ixx="0.0015" ixy="0.0" ixz="0.0" iyy="0.0015" iyz="0.0" izz="0.0015" />
        </inertial>
    </link>
    <link name="arm_link">
        <visual>
            <origin rpy="0 0 0" xyz="0 0 0" />
            <geometry>
                <mesh filename="package://niryo_robot_description/meshes/one/collada/arm_link.dae" />
            </geometry>
        </visual>
        <collision>
            <origin rpy="0 0 0" xyz="0 0 0" />
            <geometry>
                <mesh filename="package://niryo_robot_description/meshes/one/stl/arm_link.stl" />
            </geometry>
        </collision>
        <inertial>
            <origin rpy="0 0 0" xyz="0.105 -0.1 0" />
            <mass value="0.4" />
            <inertia ixx="0.0015" ixy="0.0" ixz="0.0" iyy="0.0015" iyz="0.0" izz="0.0015" />
        </inertial>
    </link>
    <link name="elbow_link">
        <visual>
            <origin rpy="0 0 0" xyz="0 0 0" />
            <geometry>
                <mesh filename="package://niryo_robot_description/meshes/one/collada/elbow_link.dae" />
            </geometry>
        </visual>
        <collision>
            <origin rpy="0 0 0" xyz="0 0 0" />
            <geometry>
                <mesh filename="package://niryo_robot_description/meshes/one/stl/elbow_link.stl" />
            </geometry>
        </collision>
        <inertial>
            <origin rpy="0 0 0" xyz="0.02075 0.015 0" />
            <mass value="0.3" />
            <inertia ixx="0.0015" ixy="0.0" ixz="0.0" iyy="0.0015" iyz="0.0" izz="0.0015" />
        </inertial>
    </link>
    <link name="forearm_link">
        <visual>
            <origin rpy="0 0 0" xyz="0 0 0" />
            <geometry>
                <mesh filename="package://niryo_robot_description/meshes/one/collada/forearm_link.dae" />
            </geometry>
        </visual>
        <collision>
            <origin rpy="0 0 0" xyz="0 0 0" />
            <geometry>
                <mesh filename="package://niryo_robot_description/meshes/one/stl/forearm_link.stl" />
            </geometry>
        </collision>
        <inertial>
            <origin rpy="0 0 0" xyz="0 0 0.09" />
            <mass value="0.3" />
            <inertia ixx="0.0015" ixy="0.0" ixz="0.0" iyy="0.0015" iyz="0.0" izz="0.0015" />
        </inertial>
    </link>
    <link name="wrist_link">
        <visual>
            <origin rpy="0 0 0" xyz="0 0 0" />
            <geometry>
                <mesh filename="package://niryo_robot_description/meshes/one/collada/wrist_link.dae" />
            </geometry>
        </visual>
        <collision>
            <origin rpy="0 0 0" xyz="0 0 0" />
            <geometry>
                <mesh filename="package://niryo_robot_description/meshes/one/stl/wrist_link.stl" />
            </geometry>
        </collision>
        <inertial>
            <origin rpy="0 0 0" xyz="0.0082 -0.00275 0" />
            <mass value="0.15" />
            <inertia ixx="0.001" ixy="0.0" ixz="0.0" iyy="0.001" iyz="0.0" izz="0.001" />
        </inertial>
    </link>
    <link name="hand_link">
        <visual>
            <origin rpy="0 0 0" xyz="0 0 0" />
            <geometry>
                <mesh filename="package://niryo_robot_description/meshes/one/collada/hand_link.dae" />
            </geometry>
        </visual>
        <collision>
            <origin rpy="0 0 0" xyz="0 0 0" />
            <geometry>
                <mesh filename="package://niryo_robot_description/meshes/one/stl/hand_link.stl" />
            </geometry>
        </collision>
        <inertial>
            <origin rpy="0 0 0" xyz="0 0 0.00365" />
            <mass value="0.05" />
            <inertia ixx="0.001" ixy="0.0" ixz="0.0" iyy="0.001" iyz="0.0" izz="0.001" />
        </inertial>
    </link>
    <link name="tool_link" />
    <!-- add collision for the motor of joint 5 -->
    <link name="joint5_motor">
        <collision>
            <origin rpy="0 0 0" xyz="-0.045 0.0 0.1765" />
            <geometry>
                <box size="0.0435 0.0285 0.0465" />
            </geometry>
        </collision>
        <inertial>
            <mass value="0.1" />
            <origin xyz="0 0 0" rpy="0 0 0" />
            <inertia ixx="0.03" iyy="0.03" izz="0.03" ixy="0.0" ixz="0.0" iyz="0.0" />
        </inertial>
    </link>
    <!--Joints -->
    <joint name="joint_world" type="fixed">
        <parent link="base_link" />
        <child link="arm_base_link" />
        <origin rpy="0 0 0" xyz="0.3 0 0" />
    </joint>
    <joint name="joint_1" type="revolute">
        <parent link="arm_base_link" />
        <child link="shoulder_link" />
        <origin rpy="0 0 0" xyz="0 0 0.103" />
        <axis xyz="0 0 1" />
        <limit effort="10.0" lower="-3.0543261909902775" upper="3.0543261909902775" velocity="2.2" />
        <dynamics damping="0.1" friction="0.0" />
    </joint>
    <joint name="joint_2" type="revolute">
        <parent link="shoulder_link" />
        <child link="arm_link" />
        <origin rpy="1.570796326795 -1.570796326795 0" xyz="0 0 0.08" />
        <limit effort="10.0" lower="-1.9100883333827199" upper="0.6400122367063628" velocity="2.2" />
        <axis xyz="0 0 1" />
        <dynamics damping="0.1" friction="0.0" />
    </joint>
    <joint name="joint_3" type="revolute">
        <parent link="arm_link" />
        <child link="elbow_link" />
        <origin rpy="0 0 -1.570796326795" xyz="0.21 0.0 0" />
        <limit effort="7.0" lower="-1.3943435394183616" upper="1.5700981950942021" velocity="2.0" />
        <axis xyz="0 0 1" />
        <dynamics damping="0.1" friction="0.0" />
    </joint>
    <joint name="joint_4" type="revolute">
        <parent link="elbow_link" />
        <child link="forearm_link" />
        <origin rpy="0 1.570796326795 0" xyz="0.0415 0.03 0" />
        <limit effort="7.0" lower="-3.050137400785491" upper="3.0543261909902775" velocity="2.0" />
        <axis xyz="0 0 1" />
        <dynamics damping="0.1" friction="0.0" />
    </joint>
    <joint name="joint_5" type="revolute">
        <parent link="forearm_link" />
        <child link="wrist_link" />
        <origin rpy="0 -1.570796326795 0" xyz="0 0 0.18" />
        <limit effort="6.0" lower="-1.7453292519944443" upper="1.9200367101190883" velocity="2.0" />
        <axis xyz="0 0 1" />
        <dynamics damping="0.1" friction="0.0" />
    </joint>
    <joint name="joint_6" type="revolute">
        <parent link="wrist_link" />
        <child link="hand_link" />
        <origin rpy="0 1.570796326795 0" xyz="0.0164 -0.0055 0" />
        <limit effort="5.0" lower="-2.530029283691147" upper="2.530029283691147" velocity="2.0" />
        <axis xyz="0 0 1" />
        <dynamics damping="0.1" friction="0.0" />
    </joint>
    <joint name="hand_tool_joint" type="fixed">
        <parent link="hand_link" />
        <child link="tool_link" />
        <origin rpy="-1.570796326795 -1.570796326795 0" xyz="0 0 0.0073" />
    </joint>
    <!-- add collision for the motor of joint 5 -->
    <joint name="joint_test" type="fixed">
        <origin rpy="0 0 0" xyz="0 0 0" />
        <parent link="forearm_link" />
        <child link="joint5_motor" />
    </joint>
    <transmission name="transmission_1">
        <type>transmission_interface/SimpleTransmission</type>
        <joint name="joint_1">
            <hardwareInterface>hardware_interface/PositionJointInterface</hardwareInterface>
        </joint>
        <actuator name="motor_1">
            <mechanicalReduction>1</mechanicalReduction>
            <hardwareInterface>hardware_interface/EffortJointInterface</hardwareInterface>
        </actuator>
    </transmission>
    <transmission name="transmission_2">
        <type>transmission_interface/SimpleTransmission</type>
        <joint name="joint_2">
            <hardwareInterface>hardware_interface/PositionJointInterface</hardwareInterface>
        </joint>
        <actuator name="motor_2">
            <mechanicalReduction>1</mechanicalReduction>
            <hardwareInterface>hardware_interface/EffortJointInterface</hardwareInterface>
        </actuator>
    </transmission>
    <transmission name="transmission_3">
        <type>transmission_interface/SimpleTransmission</type>
        <joint name="joint_3">
            <hardwareInterface>hardware_interface/PositionJointInterface</hardwareInterface>
        </joint>
        <actuator name="motor_3">
            <mechanicalReduction>1</mechanicalReduction>
            <hardwareInterface>hardware_interface/EffortJointInterface</hardwareInterface>
        </actuator>
    </transmission>
    <transmission name="transmission_4">
        <type>transmission_interface/SimpleTransmission</type>
        <joint name="joint_4">
            <hardwareInterface>hardware_interface/PositionJointInterface</hardwareInterface>
        </joint>
        <actuator name="motor_4">
            <mechanicalReduction>1</mechanicalReduction>
            <hardwareInterface>hardware_interface/EffortJointInterface</hardwareInterface>
        </actuator>
    </transmission>
    <transmission name="transmission_5">
        <type>transmission_interface/SimpleTransmission</type>
        <joint name="joint_5">
            <hardwareInterface>hardware_interface/PositionJointInterface</hardwareInterface>
        </joint>
        <actuator name="motor_5">
            <mechanicalReduction>1</mechanicalReduction>
            <hardwareInterface>hardware_interface/EffortJointInterface</hardwareInterface>
        </actuator>
    </transmission>
    <transmission name="transmission_6">
        <type>transmission_interface/SimpleTransmission</type>
        <joint name="joint_6">
            <hardwareInterface>hardware_interface/PositionJointInterface</hardwareInterface>
        </joint>
        <actuator name="motor_6">
            <mechanicalReduction>1</mechanicalReduction>
            <hardwareInterface>hardware_interface/EffortJointInterface</hardwareInterface>
        </actuator>
    </transmission>
    <!-- Joint for camera -->
    <joint name="camera_joint" type="fixed">
        <axis xyz="0 0 1" />
        <origin rpy="-1.570796326795 0 0" xyz="0 0.025 0" />
        <parent link="wrist_link" />
        <child link="camera_link" />
    </joint>
    <!-- Camera link -->
    <link name="camera_link">
        <collision>
            <origin rpy="0 0 0" xyz="0 0 0" />
            <geometry>
                <box size="0.03 0.03 0.02" />
            </geometry>
        </collision>
        <visual>
            <origin rpy="0 0 0" xyz="0 0 0" />
            <geometry>
                <box size="0.03 0.03 0.02" />
            </geometry>
            <material name="DarkGrey" />
        </visual>
        <inertial>
            <mass value="0.05" />
            <origin rpy="0 0 0" xyz="0 0 0" />
            <inertia ixx="5.4e-6" ixy="0" ixz="0" iyy="5.4e-6" iyz="0" izz="7.5e-6" />
        </inertial>
    </link>
    <!-- Add gazebo settings to make the link an camera ! -->
    <gazebo reference="camera_link">
        <material>Gazebo/DarkGrey</material>
        <sensor name="camera_gazebo" type="camera">
            <update_rate>15.0</update_rate>
            <camera name="head">
                <!--69,33 degrees-->
                <horizontal_fov>1.21</horizontal_fov>
                <!--  <aspect_ratio>1.333</aspect_ratio>-->
                <image>
                    <width>640</width>
                    <height>480</height>
                    <format>R8G8B8</format>
                </image>
                <clip>
                    <near>0.03</near>
                    <far>2</far>
                </clip>
                <distortion>
                    <k1>-0.4146402</k1>
                    <k2>0.2407384</k2>
                    <p1>-0.0</p1>
                    <p2>-0.0</p2>
                    <k3>-0.1040042</k3>
                    <center>0.5 0.5</center>
                </distortion>
            </camera>
            <plugin filename="libgazebo_ros_camera.so" name="camera_controller">
                <alwaysOn>true</alwaysOn>
                <updateRate>0.0</updateRate>
                <cameraName>gazebo_camera</cameraName>
                <imageTopicName>image_raw</imageTopicName>
                <cameraInfoTopicName>camera_info</cameraInfoTopicName>
                <frameName>camera_link</frameName>
            </plugin>
        </sensor>
        <plugin name="gazebo_ros_control">
            <robotNamespace>/</robotNamespace>
        </plugin>
    </gazebo>
    <!-- Base link -->
    <link name="base_link">
        <visual>
            <origin rpy="0 0 0" xyz="0 0 0" />
            <geometry>
                <mesh filename="package://scout_description/meshes/base_link.dae" />
            </geometry>
        </visual>
        <collision>
            <origin rpy="0 0 0" xyz="0 0 0.008" />
            <geometry>
                <box size="0.925 0.38 0.21" />
            </geometry>
        </collision>
        <collision>
            <origin rpy="0 0 0" xyz="0 0 0.034999999999999996" />
            <geometry>
                <box size="0.15416666666666667 0.627 0.06999999999999999" />
            </geometry>
        </collision>
        <inertial>
            <mass value="0.1" />
            <origin xyz="0 0 0" rpy="0 0 0" />
            <inertia ixx="0.03" iyy="0.03" izz="0.03" ixy="0.0" ixz="0.0" iyz="0.0" />
        </inertial>
    </link>
    <link name="inertial_link">
        <inertial>
            <mass value="65" />
            <inertia ixx="3.3025687499999994" ixy="0" ixz="0" iyy="5.340855" iyz="0" izz="5.340855" />
        </inertial>
    </link>
    <joint name="inertial_joint" type="fixed">
        <origin rpy="0 0 0" xyz="0 0 0" />
        <parent link="base_link" />
        <child link="inertial_link" />
    </joint>
    <!-- For testing, hang the robot up in the air -->
    <!-- <link name="world" />
    <joint name="world_to_base_link=" type="fixed">
        <origin xyz="0 0 0.5" rpy="0 0 0" />
        <parent link="world"/>
        <child link="base_link"/>
    </joint> -->
    <link name="front_right_wheel_link">
        <inertial>
            <mass value="8" />
            <origin xyz="0 0 0" rpy="0 0 0" />
            <inertia ixx="0.1171" ixy="0" ixz="0" iyy="0.1361" iyz="0" izz="0.1171" />
        </inertial>
        <visual>
            <origin rpy="0 0 0" xyz="0 0 0" />
            <geometry>
                <mesh filename="package://scout_description/meshes/wheel_type1.dae" />
            </geometry>
        </visual>
        <collision>
            <origin rpy="1.570795 0 0" xyz="0 0 0" />
            <geometry>
                <cylinder length="0.11653" radius="0.16459" />
            </geometry>
        </collision>
    </link>
    <gazebo reference="front_right_wheel_link">
        <mu1 value="1.0" />
        <mu2 value="1.0" />
        <kp value="10000000.0" />
        <kd value="1.0" />
        <fdir1 value="1 0 0" />
    </gazebo>
    <joint name="front_right_wheel" type="continuous">
        <parent link="base_link" />
        <child link="front_right_wheel_link" />
        <origin rpy="0 0 0" xyz="0.249 -0.29153 -0.0702" />
        <axis rpy="0 0 0" xyz="0 1 0" />
    </joint>
    <transmission name="front_right_wheel_trans" type="SimpleTransmission">
        <type>transmission_interface/SimpleTransmission</type>
        <actuator name="front_right_wheel_motor">
            <mechanicalReduction>1</mechanicalReduction>
            <hardwareInterface>hardware_interface/EffortJointInterface</hardwareInterface>
        </actuator>
        <joint name="front_right_wheel">
            <hardwareInterface>hardware_interface/VelocityJointInterface</hardwareInterface>
        </joint>
    </transmission>
    <link name="front_left_wheel_link">
        <inertial>
            <mass value="8" />
            <origin xyz="0 0 0" rpy="0 0 0" />
            <inertia ixx="0.1171" ixy="0" ixz="0" iyy="0.1361" iyz="0" izz="0.1171" />
        </inertial>
        <visual>
            <origin rpy="0 0 0" xyz="0 0 0" />
            <geometry>
                <mesh filename="package://scout_description/meshes/wheel_type1.dae" />
            </geometry>
        </visual>
        <collision>
            <origin rpy="1.570795 0 0" xyz="0 0 0" />
            <geometry>
                <cylinder length="0.11653" radius="0.16459" />
            </geometry>
        </collision>
    </link>
    <gazebo reference="front_left_wheel_link">
        <mu1 value="1.0" />
        <mu2 value="1.0" />
        <kp value="10000000.0" />
        <kd value="1.0" />
        <fdir1 value="1 0 0" />
    </gazebo>
    <joint name="front_left_wheel" type="continuous">
        <parent link="base_link" />
        <child link="front_left_wheel_link" />
        <origin rpy="0 0 0" xyz="0.249 0.29153 -0.0702" />
        <axis rpy="0 0 0" xyz="0 1 0" />
    </joint>
    <transmission name="front_left_wheel_trans" type="SimpleTransmission">
        <type>transmission_interface/SimpleTransmission</type>
        <actuator name="front_left_wheel_motor">
            <mechanicalReduction>1</mechanicalReduction>
            <hardwareInterface>hardware_interface/EffortJointInterface</hardwareInterface>
        </actuator>
        <joint name="front_left_wheel">
            <hardwareInterface>hardware_interface/VelocityJointInterface</hardwareInterface>
        </joint>
    </transmission>
    <link name="rear_left_wheel_link">
        <inertial>
            <mass value="8" />
            <origin xyz="0 0 0" rpy="0 0 0" />
            <inertia ixx="0.1171" ixy="0" ixz="0" iyy="0.1361" iyz="0" izz="0.1171" />
        </inertial>
        <visual>
            <origin rpy="0 0 0" xyz="0 0 0" />
            <geometry>
                <mesh filename="package://scout_description/meshes/wheel_type1.dae" />
            </geometry>
        </visual>
        <collision>
            <origin rpy="1.570795 0 0" xyz="0 0 0" />
            <geometry>
                <cylinder length="0.11653" radius="0.16459" />
            </geometry>
        </collision>
    </link>
    <gazebo reference="rear_left_wheel_link">
        <mu1 value="1.0" />
        <mu2 value="1.0" />
        <kp value="10000000.0" />
        <kd value="1.0" />
        <fdir1 value="1 0 0" />
    </gazebo>
    <joint name="rear_left_wheel" type="continuous">
        <parent link="base_link" />
        <child link="rear_left_wheel_link" />
        <origin rpy="0 0 0" xyz="-0.249 0.29153 -0.0702" />
        <axis rpy="0 0 0" xyz="0 1 0" />
    </joint>
    <transmission name="rear_left_wheel_trans" type="SimpleTransmission">
        <type>transmission_interface/SimpleTransmission</type>
        <actuator name="rear_left_wheel_motor">
            <mechanicalReduction>1</mechanicalReduction>
            <hardwareInterface>hardware_interface/EffortJointInterface</hardwareInterface>
        </actuator>
        <joint name="rear_left_wheel">
            <hardwareInterface>hardware_interface/VelocityJointInterface</hardwareInterface>
        </joint>
    </transmission>
    <link name="rear_right_wheel_link">
        <inertial>
            <mass value="8" />
            <origin xyz="0 0 0" rpy="0 0 0" />
            <inertia ixx="0.1171" ixy="0" ixz="0" iyy="0.1361" iyz="0" izz="0.1171" />
        </inertial>
        <visual>
            <origin rpy="0 0 0" xyz="0 0 0" />
            <geometry>
                <mesh filename="package://scout_description/meshes/wheel_type1.dae" />
            </geometry>
        </visual>
        <collision>
            <origin rpy="1.570795 0 0" xyz="0 0 0" />
            <geometry>
                <cylinder length="0.11653" radius="0.16459" />
            </geometry>
        </collision>
    </link>
    <gazebo reference="rear_right_wheel_link">
        <mu1 value="1.0" />
        <mu2 value="1.0" />
        <kp value="10000000.0" />
        <kd value="1.0" />
        <fdir1 value="1 0 0" />
    </gazebo>
    <joint name="rear_right_wheel" type="continuous">
        <parent link="base_link" />
        <child link="rear_right_wheel_link" />
        <origin rpy="0 0 0" xyz="-0.249 -0.29153 -0.0702" />
        <axis rpy="0 0 0" xyz="0 1 0" />
    </joint>
    <transmission name="rear_right_wheel_trans" type="SimpleTransmission">
        <type>transmission_interface/SimpleTransmission</type>
        <actuator name="rear_right_wheel_motor">
            <mechanicalReduction>1</mechanicalReduction>
            <hardwareInterface>hardware_interface/EffortJointInterface</hardwareInterface>
        </actuator>
        <joint name="rear_right_wheel">
            <hardwareInterface>hardware_interface/VelocityJointInterface</hardwareInterface>
        </joint>
    </transmission>
    <!-- This file is a placeholder which is included by default from
       husky.urdf.xacro. If a robot is being customized and requires
       additional URDF, set the HUSKY_URDF_EXTRAS environment variable
       to the full path of the file you would like included. -->
    <!-- <xacro:include filename="$(find scout_description)/urdf/scout_wheel.gazebo" /> -->
    <!-- Additional definitions for simulation -->
    <!-- <gazebo reference="base_link">
        <material>Gazebo/Grey</material>
    </gazebo> -->
    <!-- Actuator configurations -->
    <!-- <xacro:scout_wheel_transmission wheel_prefix="front_right" />
    <xacro:scout_wheel_transmission wheel_prefix="front_left" />
    <xacro:scout_wheel_transmission wheel_prefix="rear_left" />
    <xacro:scout_wheel_transmission wheel_prefix="rear_right" /> -->
    <!-- Controller configurations -->
    <gazebo>
        <plugin filename="libgazebo_ros_control.so" name="gazebo_ros_control">
            <robotNamespace>/</robotNamespace>
        </plugin>
    </gazebo>
    <!-- kp spring constant, kd damping constant -->
    <!-- <gazebo reference="front_left_wheel">
        <mu1>10</mu1>
        <mu2>10</mu2>
        <kp>10000000.0</kp>
        <kd>1.0</kd>
        <minDepth>0.01</minDepth>
        <fdir1>1 0 0</fdir1>
        <maxContacts value="64"/>
    </gazebo>
    <gazebo reference="front_right_wheel">
        <mu1>10</mu1>
        <mu2>10</mu2>
        <kp>10000000.0</kp>
        <kd>1.0</kd>
        <minDepth>0.01</minDepth>
        <fdir1>1 0 0</fdir1>
        <maxContacts value="64"/>
    </gazebo>
    <gazebo reference="rear_left_wheel">
        <mu1>10</mu1>
        <mu2>10</mu2>
        <kp>10000000.0</kp>
        <kd>1.0</kd>
        <minDepth>0.01</minDepth>
        <fdir1>1 0 0</fdir1>
        <maxContacts value="64"/>
    </gazebo>
    <gazebo reference="rear_right_wheel">
        <mu1>10</mu1>
        <mu2>10</mu2>
        <kp>10000000.0</kp>
        <kd>1.0</kd>
        <minDepth>0.01</minDepth>
        <fdir1>1 0 0</fdir1>
        <maxContacts value="64"/>
    </gazebo> -->
    <gazebo>
        <plugin filename="libhector_gazebo_ros_imu.so" name="imu_controller">
            <robotNamespace>/</robotNamespace>
            <updateRate>50.0</updateRate>
            <bodyName>base_link</bodyName>
            <topicName>imu/data</topicName>
            <accelDrift>0.005 0.005 0.005</accelDrift>
            <accelGaussianNoise>0.005 0.005 0.005</accelGaussianNoise>
            <rateDrift>0.005 0.005 0.005</rateDrift>
            <rateGaussianNoise>0.005 0.005 0.005</rateGaussianNoise>
            <headingDrift>0.005</headingDrift>
            <headingGaussianNoise>0.005</headingGaussianNoise>
        </plugin>
    </gazebo>
    <!-- <gazebo>
        <plugin name="skid_steer_drive_controller" filename="libgazebo_ros_skid_steer_drive.so">
            <updateRate>100.0</updateRate>
            <robotNamespace></robotNamespace>
            <leftFrontJoint>front_left_wheel</leftFrontJoint>
            <rightFrontJoint>front_right_wheel</rightFrontJoint>
            <leftRearJoint>rear_left_wheel</leftRearJoint>
            <rightRearJoint>rear_right_wheel</rightRearJoint>
            <wheelSeparation>4</wheelSeparation>
            <wheelDiameter>0.32918</wheelDiameter>
            <robotBaseFrame>base_link</robotBaseFrame>
            <torque>1000</torque>
            <commandTopic>cmd_vel</commandTopic>
            <broadcastTF>true</broadcastTF>
            <odometryTopic>odom</odometryTopic>
            <odometryFrame>odom</odometryFrame>
            <covariance_x>0.000100</covariance_x>
            <covariance_y>0.000100</covariance_y>
            <covariance_yaw>0.010000</covariance_yaw>
        </plugin>
    </gazebo> -->
    <!-- <gazebo>
        <plugin name="object_controller" filename="libgazebo_ros_planar_move.so">
            <commandTopic>cmd_vel</commandTopic>
            <odometryTopic>odom</odometryTopic>
            <odometryFrame>odom</odometryFrame>
            <odometryRate>20.0</odometryRate>
            <robotBaseFrame>base_footprint</robotBaseFrame>
        </plugin>
    </gazebo> -->
    <link name="base_laser_mount">
        <visual>
            <origin rpy="0 0 -1.570795" xyz="0 0 0" />
            <geometry>
                <!-- Origin of this mesh is the base of the bracket. -->
                <mesh filename="package://scout_description/meshes/accessories/lms1xx_mount.dae" />
            </geometry>
        </visual>
        <collision>
            <origin rpy="0 0 0" xyz="0 0 .0585" />
            <geometry>
                <box size=".1 .108 .117" />
            </geometry>
        </collision>
        <inertial>
            <mass value="0.1" />
            <origin xyz="0 0 0" rpy="0 0 0" />
            <inertia ixx="0.03" iyy="0.03" izz="0.03" ixy="0.0" ixz="0.0" iyz="0.0" />
        </inertial>
    </link>
    <joint name="base_laser_joint" type="fixed">
        <!-- This offset is from the base of the bracket to the LIDAR's focal point. -->
        <origin rpy="3.14159 0 0" xyz="0.0352 0 0.0566" />
        <parent link="base_laser_mount" />
        <child link="base_laser" />
    </joint>
    <link name="base_laser">
        <inertial>
            <mass value="1.1" />
            <origin xyz="0 0 0" rpy="0 0 0" />
            <inertia ixx="0.00307156543804" ixy="0.0" ixz="0.0" iyy="0.0031284904152700005" iyz="0.0" izz="0.00196432421427" />
        </inertial>
        <visual>
            <origin rpy="0 0 0" xyz="0 0 0" />
            <geometry>
                <!-- Origin of this mesh is the focal point of the LIDAR. -->
                <mesh filename="package://lms1xx/meshes/sick-lms1xx.dae" />
            </geometry>
        </visual>
        <collision>
            <origin rpy="0 0 0" xyz="0 0 -0.05" />
            <geometry>
                <box size="0.105 0.1 0.1" />
            </geometry>
        </collision>
    </link>
    <gazebo reference="base_laser">
        <turnGravityOff>true</turnGravityOff>
        <sensor name="base_laser" type="ray">
            <pose>0 0 0 0 0 0</pose>
            <visualize>false</visualize>
            <update_rate>50</update_rate>
            <ray>
                <scan>
                    <horizontal>
                        <samples>720</samples>
                        <resolution>1</resolution>
                        <min_angle>-2.35619</min_angle>
                        <max_angle>2.35619</max_angle>
                    </horizontal>
                </scan>
                <range>
                    <min>0.1</min>
                    <max>30.0</max>
                    <resolution>0.01</resolution>
                </range>
                <noise>
                    <type>gaussian</type>
                    <mean>0.0</mean>
                    <stddev>0.001</stddev>
                </noise>
            </ray>
            <plugin filename="libgazebo_ros_laser.so" name="gazebo_ros_laser">
                <topicName>scan</topicName>
                <frameName>base_laser</frameName>
                <robotNamespace>/</robotNamespace>
            </plugin>
        </sensor>
    </gazebo>
    <joint name="laser_mount_joint" type="fixed">
        <origin rpy="0 0 0" xyz="-0.2 0 0.4" />
        <parent link="base_link" />
        <child link="base_laser_mount" />
    </joint>
    <!-- <xacro:vlp16_mount prefix="" parent_link="base_link" topic="points">
        <origin xyz="-0.2 0 0.4" rpy="0 0 0" />
        </xacro:vlp16_mount> -->
</robot>

